Workbook

Sheet Dashboard
A1: BAKER HUGHES / CHART INDUSTRIES — TRANSACTION DASHBOARD
A2: Precedent Transactions Analysis | $ in millions, except per-share data and multiples | Status as of 21 August 2026
A4: HEADLINE TRANSACTION TERMS AND VALUATION CONCLUSION
A5: Transaction Metric | B5: Value | C5: PTA / Comparable Metric | D5: Value | E5: VALUATION CONCLUSION
A6: Buyer | B6: ='Transaction Overview'!B6 -> Baker Hughes Company | C6: Transaction Status | D6: ='Transaction Overview'!B27 -> Completed | E6: ="PTA Implied Value = "&TEXT('PTA Valuation'!B40,"$0.00")&"/share" -> PTA Implied Value = $156.03/share
A7: Target | B7: ='Transaction Overview'!B7 -> Chart Industries, Inc. | C7: EV / Revenue | D7: ='Transaction Overview'!B24 -> 3.268995 | E7: ="Baker Hughes Offer Price = "&TEXT('Transaction Overview'!B10,"$0.00")&"/share" -> Baker Hughes Offer Price = $210.00/share
A8: Announcement Date | B8: ='Transaction Overview'!B8 -> 45867 | C8: EV / Adjusted EBITDA | D8: ='Transaction Overview'!B25 -> 13.414875 | E8: ="Offer Premium vs. PTA (Offer / PTA - 1) = "&TEXT('Transaction Overview'!B10/'PTA Valuation'!B40-1,"0.0%") -> Offer Premium vs. PTA (Offer / PTA - 1) = 34.6%
A9: Completion Date | B9: ='Transaction Overview'!B9 -> 46219 | C9: Core Precedent Transactions | D9: ='Sources & Checks'!B42 -> 8 | E9: ="PTA Discount vs. Offer (PTA / Offer - 1) = "&TEXT('PTA Valuation'!B40/'Transaction Overview'!B10-1,"0.0%") -> PTA Discount vs. Offer (PTA / Offer - 1) = -25.7%
A10: Offer Price / Share | B10: ='Transaction Overview'!B10 -> 210 | C10: Median EV / Revenue | D10: ='Transaction Multiples'!B30 -> 2.4027165 | E10: Reference Price | F10: $/Share
A11: Unaffected Share Price | B11: ='Transaction Overview'!B11 -> 171.65 | C11: Median EV / EBITDA | D11: ='Transaction Multiples'!C30 -> 11.806438 | E11: Unaffected Price | F11: ='Transaction Overview'!B11 -> 171.65
A12: Transaction Premium | B12: ='Transaction Overview'!B12 -> 0.22341975 | C12: Median Precedent Premium | D12: ='Premium Analysis'!B23 -> 0.44088992 | E12: PTA Value | F12: ='PTA Valuation'!B40 -> 156.03353
A13: Enterprise Value | B13: ='Transaction Overview'!B14 -> 13600 | C13: PTA Implied Share Price | D13: ='PTA Valuation'!B40 -> 156.03353 | E13: Offer Price | F13: ='Transaction Overview'!B10 -> 210
A14: Implied Equity Value — FY2024 Net Debt Basis | B14: ='Transaction Overview'!B13 -> 10267 | C14: Offer Price vs. PTA Value | D14: =$B$10/D13-1 -> 0.34586454
C15: Unaffected Price vs. PTA Value | D15: =$B$11/D13-1 -> 0.10008404
A16: VALUATION SNAPSHOT — PRECEDENT TRANSACTIONS ANALYSIS
A17: Method | B17: Low (25th) | C17: Median | D17: High (75th)
A18: EV / Revenue Implied Share Price | B18: ='PTA Valuation'!I17 -> 102.72662 | C18: ='PTA Valuation'!I18 -> 135.90802 | D18: ='PTA Valuation'!I19 -> 148.64043
A19: EV / EBITDA Implied Share Price | B19: ='PTA Valuation'!I25 -> 155.72947 | C19: ='PTA Valuation'!I26 -> 176.15905 | D19: ='PTA Valuation'!I27 -> 206.25251
A20: Blended Implied Share Price | B20: ='PTA Valuation'!H34 -> 129.22805 | C20: ='PTA Valuation'!I34 -> 156.03353 | D20: ='PTA Valuation'!J34 -> 177.44647
A22: SELECTED BASE CASE AND REFERENCE PRICES
A23: Reference | B23: Value | C23: Note
A24: Selected PTA Base Case (Blended Median) | B24: ='PTA Valuation'!B40 -> 156.03353 | C24: Analyst selection
A25: Premium / (Discount) to Unaffected | B25: ='PTA Valuation'!B41 -> -0.090978539 | C25: vs $171.65 unaffected price
A26: Premium / (Discount) to Offer | B26: ='PTA Valuation'!B42 -> -0.25698317 | C26: vs $210.00 offer price
A28: PRECEDENT SET AND MODEL INTEGRITY
A29: Metric | B29: Value
A30: Core Precedent Transactions | B30: ='Sources & Checks'!B42 -> 8
A31: Median EV / Revenue | B31: ='Transaction Multiples'!B30 -> 2.4027165
A32: Median EV / EBITDA | B32: ='Transaction Multiples'!C30 -> 11.806438
A33: Median Premium (Verified Observations) | B33: ='Transaction Multiples'!D30 -> 0.44088992
A34: Overall Data Quality Status | B34: ='Sources & Checks'!B65 -> PASS
A36: ="Offer premium of "&TEXT('Premium Analysis'!B8,"0.0%")&" is below the verified precedent 25th–75th range of "&TEXT('Premium Analysis'!B22,"0.0%")&"–"&TEXT('Premium Analysis'!B24,"0.0%")&"; precedent median is "&TEXT('Premium Analysis'!B23,"0.0%")&"." -> Offer premium of 22.3% is below the verified precedent 25th–75th range of 33.7%–52.8%; precedent median is 44.1%.
A37: The disclosed ~9.0x 2025E forward, synergy-adjusted transaction multiple is excluded from the historical PTA because it is forward-looking and includes buyer synergies. The valuation denominator is 49.026mm signing-date fully diluted share equivalents from the proxy filing-fee capitalization.

Sheet Transaction Overview
A1: BAKER HUGHES / CHART INDUSTRIES — TRANSACTION OVERVIEW
A2: Precedent Transactions Analysis | $ in millions, except per-share data and multiples | Status as of 21 August 2026
A4: FOCAL TRANSACTION — REPORTED AND CALCULATED TERMS
A5: Transaction Detail | B5: Value | C5: Data Classification | D5: Source ID | H5: MODEL COLOR CONVENTION
A6: Buyer | B6: Baker Hughes Company | C6: Reported | D6: S01 | H6: Blue font | I6: Editable assumption / scenario driver
A7: Target | B7: Chart Industries, Inc. | C7: Reported | D7: S01 | H7: Green font | I7: Link to another worksheet
A8: Announcement Date | B8: 45867 | C8: Reported | D8: S01 | H8: Black font | I8: Formula, calculation or reported historical value
A9: Completion Date | B9: 46219 | C9: Reported | D9: S04 | H9: Red font | I9: External workbook link or model error
A10: Offer Price / Share ($) | B10: 210 | C10: Reported | D10: S01
A11: Unaffected Share Price ($) | B11: 171.65 | C11: Reported — 28 Jul 2025 close | D11: S03
A12: Transaction Premium | B12: =B10/B11-1 -> 0.22341975 | C12: Calculated | D12: S03
A13: Implied Equity Value ($mm) | B13: =B14-B17 -> 10267 | C13: Calculated: EV less FY2024A net debt | D13: S01 / S05 | E13: Calculated as transaction EV less FY2024A net debt.
A14: Enterprise Value ($mm) | B14: 13600 | C14: Reported | D14: S01
A15: Target Debt ($mm) | B15: 3641.6 | C15: Reported — FY2024A | D15: S05
A16: Target Cash ($mm) | B16: 308.6 | C16: Reported — FY2024A | D16: S05
A17: Target Net Debt ($mm) | B17: =B15-B16 -> 3333 | C17: Calculated | D17: S05
A18: Consideration Type | B18: All cash | C18: Reported | D18: S01
A19: Financing Structure | B19: Committed bridge; permanent funding from cash on hand and debt issuance | C19: Reported | D19: S02 / S04
A20: Expected Cost Synergies ($mm) | B20: 325 | C20: Reported — run-rate by Year 3 | D20: S01
A21: Expected Closing Net Leverage | B21: 2.25 | C21: Reported | D21: S01
A22: Leverage Target (within 24 months) | B22: 1.0x–1.5x | C22: Reported | D22: S01
A23: Disclosed Transaction Multiple | B23: ~9.0x 2025E consensus EBITDA, including run-rate cost synergies | C23: Reported / forward | D23: S02
A24: FY2024A EV / Revenue | B24: =B14/'Target Financials'!D6 -> 3.268995 | C24: Calculated — historical actual | D24: S01 / S05
A25: FY2024A EV / Adjusted EBITDA | B25: =B14/'Target Financials'!D11 -> 13.414875 | C25: Calculated — historical actual | D25: S01 / S05
A26: Accretion | B26: Double-digit adjusted EPS accretion in first full calendar year after close | C26: Reported; adjusted EPS basis | D26: S01
A27: Transaction Status | B27: Completed | C27: Reported | D27: S04
A29: STRATEGIC RATIONALE AND TRANSACTION INTERPRETATION
A30: Theme | B30: Reported Rationale / Interpretation | C30: Classification | D30: Source ID
A31: Portfolio | B31: Adds cryogenic and process technologies and expands high-value industrial exposure. | C31: Reported / summarized | D31: S01
A32: End Markets | B32: Deepens exposure to LNG, data centers, hydrogen, carbon capture and other energy-transition infrastructure. | C32: Reported / summarized | D32: S01
A33: Aftermarket | B33: Expands installed base and recurring aftermarket service opportunity. | C33: Reported / summarized | D33: S01
A34: PTA Interpretation | B34: The disclosed ~9.0x multiple is forward and synergy-adjusted; it is shown separately from the historical precedent statistics. | C34: Analyst interpretation | D34: S02
A36: Important: the focal transaction is not included in the precedent statistics. The core precedent set uses verified historical financial periods. Forward or incomplete reference transactions are shown separately and excluded from the affected statistics.
A40: TRANSACTION TIMELINE
A41: ANNOUNCEMENT | E41: REGULATORY / SHAREHOLDER PROCESS | I41: COMPLETION
A42: =B8 -> 45867 | E42: Post-announcement through closing | I42: =B9 -> 46219
A43: Baker Hughes announced the all-cash acquisition of Chart Industries at $210 per share. Source: S01. | E43: Regulatory, merger-proxy and shareholder processes proceeded between announcement and completion. Source: S03. | I43: Baker Hughes completed the acquisition and funded closing with cash on hand and debt financing. Source: S04.

Sheet Target Financials
A1: CHART INDUSTRIES — TARGET FINANCIALS
A2: Historical financial spreading | $ in millions, shares in millions | FY2024A selected for PTA valuation
A4: HISTORICAL FINANCIALS AND CAPITALIZATION
A5: Financial Metric | B5: FY2022A | C5: FY2023A | D5: FY2024A | E5: FY2025A | F5: Definition / Data Status
A6: Revenue | B6: 1612.4 | C6: 3352.5 | D6: 4160.3 | E6: 4264 | F6: Reported actual
A7: EBIT / Operating Income | B7: 151.5 | C7: 390.7 | D7: 647.5 | E7: 358.4 | F7: Reported actual
A8: D&A | B8: 81.9 | C8: 231.1 | D8: 269.9 | E8: 281.3 | F8: Reported actual
A9: Standardized EBITDA | B9: =B7+B8 -> 233.4 | C9: =C7+C8 -> 621.8 | D9: =D7+D8 -> 917.4 | E9: =E7+E8 -> 639.7 | F9: Calculated: EBIT + D&A
A10: Company-Reported EBITDA | B10: 249.1 | C10: 680.3 | D10: 914 | E10: 625.7 | F10: Reported; FY2023 presented on company pro forma basis
A11: Adjusted EBITDA | B11: 296.3 | C11: 774.8 | D11: 1013.8 | E11: 1014.3 | F11: Reported non-GAAP; FY2023 pro forma includes Howden pre-close stub
A12: Net Income | B12: 25 | C12: 56.9 | D12: 232.8 | E12: 37.2 | F12: Reported consolidated net income
A13: Cash | B13: 663.6 | C13: 188.3 | D13: 308.6 | E13: 366 | F13: Reported year-end
A14: Total Debt | B14: 2318 | C14: 3834.9 | D14: 3641.6 | E14: 3565 | F14: Reported year-end
A15: Net Debt | B15: =B14-B13 -> 1654.4 | C15: =C14-C13 -> 3646.6 | D15: =D14-D13 -> 3333 | E15: =E14-E13 -> 3199 | F15: Calculated: Total Debt less Cash
A16: Year-End Common Shares | B16: 41.802 | C16: 41.993 | D16: 44.896 | E16: 47.797 | F16: Reported / calculated from issued less treasury where applicable
A17: Diluted Weighted Average Shares | B17: 36.5 | C17: 46.82 | D17: 46.67 | E17: 45.37 | F17: Reported; FY2022 rounded to one decimal
A18: Capital Expenditures | B18: 74.2 | C18: 135.6 | D18: 120.8 | E18: 89.9 | F18: Reported cash capex
A19: Operating Cash Flow | B19: 80.8 | C19: 234.8 | D19: 508.7 | E19: 292.7 | F19: Reported cash from continuing operations
A22: PTA VALUATION INPUT SELECTION
A23: Selected Input | B23: Value | C23: Basis | D23: Rationale
A24: Revenue | B24: =D6 -> 4160.3 | C24: FY2024A reported actual | D24: Last complete fiscal year immediately before announcement
A25: Adjusted EBITDA | B25: =D11 -> 1013.8 | C25: FY2024A company-reported adjusted | D25: Consistent with Chart transaction communication and operating presentation
A26: Net Debt | B26: =D15 -> 3333 | C26: FY2024A calculated | D26: FY2024A debt less cash
A27: Diluted Shares | B27: ='Target Capitalization'!B9 -> 49.025963 | C27: Signing-date fully diluted share equivalents | D27: Proxy filing-fee capitalization; FY2024A diluted WA remains in D17
A28: Unaffected Share Price | B28: ='Transaction Overview'!B11 -> 171.65 | C28: 28-Jul-2025 close | D28: Last trading day before announcement
A29: Offer Price | B29: ='Transaction Overview'!B10 -> 210 | C29: Reported | D29: Cash consideration per share
A32: Period discipline: FY2024A is the selected historical base because it is the final completed fiscal year before the July 2025 transaction announcement. FY2025A is retained as post-announcement actual history and is not mixed into the historical PTA multiple application.
A36: HISTORICAL KPI AND CASH FLOW ANALYSIS
A37: Calculated Metric | B37: FY2022A | C37: FY2023A | D37: FY2024A | E37: FY2025A | F37: Definition
A38: Revenue Growth | B38: Not applicable | C38: =C6/B6-1 -> 1.0791987 | D38: =D6/C6-1 -> 0.24095451 | E38: =E6/D6-1 -> 0.024926087 | F38: Calculated year-over-year
A39: EBIT Margin | B39: =B7/B$6 -> 0.093959315 | C39: =C7/C$6 -> 0.1165399 | D39: =D7/D$6 -> 0.15563781 | E39: =E7/E$6 -> 0.084052533 | F39: EBIT / Revenue
A40: Standardized EBITDA Margin | B40: =B9/B$6 -> 0.14475316 | C40: =C9/C$6 -> 0.18547353 | D40: =D9/D$6 -> 0.22051294 | E40: =E9/E$6 -> 0.15002345 | F40: Standardized EBITDA / Revenue
A41: Adjusted EBITDA Margin | B41: =B11/B$6 -> 0.18376333 | C41: =C11/C$6 -> 0.23111111 | D41: =D11/D$6 -> 0.24368435 | E41: =E11/E$6 -> 0.23787523 | F41: Adjusted EBITDA / Revenue
A42: Net Margin | B42: =B12/B$6 -> 0.015504838 | C42: =C12/C$6 -> 0.016972409 | D42: =D12/D$6 -> 0.055957503 | E42: =E12/E$6 -> 0.0087242026 | F42: Net Income / Revenue
A43: Net Debt / Adjusted EBITDA | B43: =B15/B11 -> 5.5835302 | C43: =C15/C11 -> 4.7065049 | D43: =D15/D11 -> 3.2876307 | E43: =E15/E11 -> 3.1538992 | F43: Net Debt / Adjusted EBITDA
A44: Free Cash Flow | B44: =B19-B18 -> 6.6 | C44: =C19-C18 -> 99.2 | D44: =D19-D18 -> 387.9 | E44: =E19-E18 -> 202.8 | F44: Operating Cash Flow less Capex
A45: FCF Conversion | B45: =B44/B11 -> 0.022274722 | C45: =C44/C11 -> 0.12803304 | D45: =D44/D11 -> 0.38261985 | E45: =E44/E11 -> 0.19994085 | F45: Free Cash Flow / Adjusted EBITDA
A47: FY2024A is the primary PTA valuation period because it was the latest completed full fiscal year before the July 2025 announcement. FY2025A remains visible as post-announcement actual history and is not mixed into the historical multiple application. FCF conversion is defined as FCF divided by Adjusted EBITDA.

Sheet Target Capitalization
A1: CHART INDUSTRIES — CAPITALIZATION
A2: Fully diluted share count and enterprise-to-equity bridge | $ in millions, except per-share data
A4: SHARE CAPITALIZATION — REFERENCE AND VALUATION
A5: Item | B5: Shares (mm) | C5: Basis
A6: Year-End Common Shares Outstanding — FY2024A | B6: 44.896 | C6: Reported year-end; secondary reference
A7: Diluted Weighted Average Shares — FY2024A | B7: 46.67 | C7: Reported FY2024A diluted WA; secondary reference
A8: Issued Common Shares — Proxy Filing Date | B8: =B30 -> 44.951215 | C8: 44.951mm issued common shares as of 26-Aug-2025
A9: Selected Fully Diluted Shares for Valuation | B9: =B34 -> 49.025963 | C9: Signing-date fully diluted share equivalents; S09
A11: ENTERPRISE VALUE TO EQUITY VALUE BRIDGE — AT OFFER
A12: Item | B12: Value | C12: Basis
A13: Reported Transaction Enterprise Value | B13: ='Transaction Overview'!B14 -> 13600 | C13: Reported deal EV
A14: Less: Total Debt (FY2024A) | B14: =-'Target Financials'!D14 -> -3641.6 | C14: Reported year-end
A15: Plus: Cash & Equivalents (FY2024A) | B15: ='Target Financials'!D13 -> 308.6 | C15: Reported year-end
A16: Implied Equity Value — FY2024 Net Debt Basis | B16: =B13+B14+B15 -> 10267 | C16: Calculated: reported EV less FY2024A net debt
A17: Implied Value per Share — FY2024 Net Debt Basis | B17: =B16/B9 -> 209.41965 | C17: Equity value / diluted shares
A18: Difference vs. Contractual $210 Offer Price | B18: =B17-'Transaction Overview'!B10 -> -0.5803497 | C18: Approximate EV / FY2024 net debt bridge versus proxy filing-fee consideration
A20: MARKET CAPITALIZATION AT KEY REFERENCE PRICES
A21: Reference Price | B21: Price / Share | C21: Diluted Shares | D21: Implied Equity Value | E21: Plus Net Debt | F21: Implied EV
A22: Unaffected (28-Jul-2025) | B22: ='Target Financials'!B28 -> 171.65 | C22: =$B$9 -> 49.025963 | D22: =B22*C22 -> 8415.3065 | E22: ='Target Financials'!B26 -> 3333 | F22: =D22+E22 -> 11748.307
A23: Offer Price | B23: ='Target Financials'!B29 -> 210 | C23: =$B$9 -> 49.025963 | D23: =B23*C23 -> 10295.452 | E23: ='Target Financials'!B26 -> 3333 | F23: =D23+E23 -> 13628.452
A24: Selected PTA Base Case | B24: ='PTA Valuation'!B40 -> 156.03353 | C24: =$B$9 -> 49.025963 | D24: =B24*C24 -> 7649.6942 | E24: ='Target Financials'!B26 -> 3333 | F24: =D24+E24 -> 10982.694
A26: FY2024A diluted weighted-average shares are retained as a secondary historical reference. The valuation denominator is the proxy filing-fee fully diluted share-equivalent count, which includes common shares, preferred conversion shares and the economic value of equity awards.
A28: SIGNING-DATE FULLY DILUTED SHARE COUNT — PROXY FILING FEE
A29: Item | B29: Value | C29: Interpretation
A30: Issued Common Shares | B30: 44.951215 | C30: Issued and outstanding as of 26-Aug-2025
A31: Preferred Conversion Share Equivalents | B31: 3.405955 | C31: Shares reserved for Series B preferred conversion
A32: Equity Award / Option Economic Equivalents | B32: 0.66879287 | C32: RSUs, PSUs, anticipated grants and net option consideration equivalents
A33: Proxy Maximum Transaction Valuation ($mm) | B33: 10295.452 | C33: SEC filing-fee transaction value; S09
A34: Signing-Date Fully Diluted Share Equivalents | B34: =SUM(B30:B32) -> 49.025963 | C34: Selected valuation denominator; component sum and transaction-value cross-check
A36: Proxy filing-fee values are used to establish a share-count-consistent denominator. The disclosed $13.6bn enterprise value is rounded and FY2024A net debt is a historical analytical bridge, so it is not expected to reproduce the proxy transaction valuation exactly.

Sheet Precedent Transactions
A1: PRECEDENT TRANSACTIONS — SCREENED COMPARABLE SET
A2: Core set requires verified EV, revenue and EBITDA for a consistent historical calculation; $ in millions
A4: CORE PRECEDENT SET — INCLUDED IN EV / REVENUE AND EV / EBITDA STATISTICS
A5: # | B5: Buyer | C5: Target | D5: Announcement | E5: Completion / Status | F5: Transaction Type | G5: Equity Value | H5: Enterprise Value | I5: Financial Period | J5: Revenue | K5: EBITDA | L5: EBITDA Basis | M5: EV / Revenue | N5: EV / EBITDA | O5: Offer Price | P5: Unaffected Price | Q5: Premium | R5: Consideration | S5: Strategic Rationale | T5: Source ID | U5: Statistical Inclusion | V5: Duplicate Count | W5: EV / Revenue Check | X5: EV / EBITDA Check | Y5: Units Check | Z5: Industry
A6: 1 | B6: Flowserve | C6: Velan | D6: 44967 | E6: Terminated — 05-Oct-2023 | F6: Public strategic | G6: 209 | H6: 245 | I6: LTM Nov-2022 | J6: 380 | K6: 21 | L6: Reported EBITDA | M6: =H6/J6 -> 0.64473684 | N6: =H6/K6 -> 11.666667 | O6: 13 | P6: 6.5 | Q6: =O6/P6-1 -> 1 | R6: All cash | S6: Valves, cryogenic, nuclear and defense exposure; aftermarket expansion. | T6: S10 / S11 | U6: Core — both | V6: =COUNTIFS($B$6:$B$13,B6,$C$6:$C$13,C6) -> 1 | W6: =IF(ABS(M6-H6/J6)<0.0001,"PASS","REVIEW") -> PASS | X6: =IF(ISNUMBER(SEARCH("implied by disclosed",L6)),"DERIVED — DISCLOSED MULTIPLE",IF(ABS(N6-H6/K6)<0.0001,"PASS","REVIEW")) -> PASS | Y6: PASS | Z6: Flow control / industrial valves
A7: 2 | B7: SLB | C7: ChampionX | D7: 45384 | E7: Completed — 16-Jul-2025 | F7: Public strategic | G7: 7700 | H7: 8012 | I7: FY2023A | J7: 3759 | K7: 771.221 | L7: Adjusted EBITDA | M7: =H7/J7 -> 2.1314179 | N7: =H7/K7 -> 10.388721 | O7: Not disclosed | P7: Not disclosed | Q7: 0.147 | R7: All stock | S7: Production chemicals, artificial lift and digital production optimization. | T7: S12 / S13 / S14 | U7: Core — both | V7: =COUNTIFS($B$6:$B$13,B7,$C$6:$C$13,C7) -> 1 | W7: =IF(ABS(M7-H7/J7)<0.0001,"PASS","REVIEW") -> PASS | X7: =IF(ISNUMBER(SEARCH("implied by disclosed",L7)),"DERIVED — DISCLOSED MULTIPLE",IF(ABS(N7-H7/K7)<0.0001,"PASS","REVIEW")) -> PASS | Y7: PASS | Z7: Oilfield services / production technology
A8: 3 | B8: Emerson | C8: National Instruments | D8: 45028 | E8: Completed — 11-Oct-2023 | F8: Public strategic | G8: 8200 | H8: 8653 | I8: FY2022A | J8: 1656.975 | K8: 282.776 | L8: Standardized EBITDA: EBIT + D&A | M8: =H8/J8 -> 5.2221669 | N8: =H8/K8 -> 30.600192 | O8: 60 | P8: 40.17 | Q8: =O8/P8-1 -> 0.49365198 | R8: All cash | S8: Test-and-measurement automation, software and discrete industrial exposure. | T8: S15 / S16 / S17 | U8: Core — both | V8: =COUNTIFS($B$6:$B$13,B8,$C$6:$C$13,C8) -> 1 | W8: =IF(ABS(M8-H8/J8)<0.0001,"PASS","REVIEW") -> PASS | X8: =IF(ISNUMBER(SEARCH("implied by disclosed",L8)),"DERIVED — DISCLOSED MULTIPLE",IF(ABS(N8-H8/K8)<0.0001,"PASS","REVIEW")) -> PASS | Y8: PASS | Z8: Industrial automation / test & measurement
A9: 4 | B9: Regal Rexnord | C9: Altra Industrial Motion | D9: 44861 | E9: Completed — 27-Mar-2023 | F9: Public strategic | G9: 4090 | H9: 4950 | I9: LTM Sep-2022 | J9: 1945.9 | K9: 363.9706 | L9: Adjusted EBITDA implied by disclosed 13.6x | M9: =H9/J9 -> 2.5438101 | N9: =H9/K9 -> 13.6 | O9: 62 | P9: 40.2597 | Q9: =O9/P9-1 -> 0.54000154 | R9: All cash | S9: Motion control, automation and industrial powertrain scale. | T9: S18 / S19 / S20 | U9: Core — both | V9: =COUNTIFS($B$6:$B$13,B9,$C$6:$C$13,C9) -> 1 | W9: =IF(ABS(M9-H9/J9)<0.0001,"PASS","REVIEW") -> PASS | X9: =IF(ISNUMBER(SEARCH("implied by disclosed",L9)),"DERIVED — DISCLOSED MULTIPLE",IF(ABS(N9-H9/K9)<0.0001,"PASS","REVIEW")) -> DERIVED — DISCLOSED MULTIPLE | Y9: PASS | Z9: Industrial motion control / engineered products
A10: 5 | B10: Chart Industries | C10: Howden | D10: 44874 | E10: Completed — 17-Mar-2023 | F10: Private strategic | G10: 4404.9 | H10: 4404.9 | I10: LTM Aug/Sep-2022 | J10: 1800 | K10: 335 | L10: Pro forma adjusted EBITDA | M10: =H10/J10 -> 2.4471667 | N10: =H10/K10 -> 13.148955 | O10: Not disclosed | P10: Not disclosed | Q10: Not disclosed | R10: Cash / financed | S10: Compressors, blowers and aftermarket across LNG, hydrogen and CCUS. | T10: S21 / S22 / S23 | U10: Core — both | V10: =COUNTIFS($B$6:$B$13,B10,$C$6:$C$13,C10) -> 1 | W10: =IF(ABS(M10-H10/J10)<0.0001,"PASS","REVIEW") -> PASS | X10: =IF(ISNUMBER(SEARCH("implied by disclosed",L10)),"DERIVED — DISCLOSED MULTIPLE",IF(ABS(N10-H10/K10)<0.0001,"PASS","REVIEW")) -> PASS | Y10: PASS | Z10: Industrial compression / process technology
A11: 6 | B11: Siemens | C11: Dresser-Rand | D11: 41904 | E11: Completed — 30-Jun-2015 | F11: Public strategic | G11: 6400 | H11: 7600 | I11: FY2013A | J11: 2946.19 | K11: 693.32 | L11: Standardized EBITDA: EBIT + D&A | M11: =H11/J11 -> 2.5796028 | N11: =H11/K11 -> 10.961749 | O11: 83 | P11: Not disclosed | Q11: Not disclosed | R11: All cash | S11: Compressors and turbines; energy infrastructure and installed-base services. | T11: S24 / S25 / S26 | U11: Core — both | V11: =COUNTIFS($B$6:$B$13,B11,$C$6:$C$13,C11) -> 1 | W11: =IF(ABS(M11-H11/J11)<0.0001,"PASS","REVIEW") -> PASS | X11: =IF(ISNUMBER(SEARCH("implied by disclosed",L11)),"DERIVED — DISCLOSED MULTIPLE",IF(ABS(N11-H11/K11)<0.0001,"PASS","REVIEW")) -> PASS | Y11: PASS | Z11: Energy infrastructure / rotating equipment
A12: 7 | B12: KKR | C12: Gardner Denver | D12: 41341 | E12: Completed — 30-Jul-2013 | F12: Sponsor take-private | G12: 3782 | H12: 3900 | I12: FY2012A | J12: 2360 | K12: 469.8795 | L12: EBITDA implied by disclosed 8.3x | M12: =H12/J12 -> 1.6525424 | N12: =H12/K12 -> 8.3000003 | O12: 76 | P12: 54.75 | Q12: =O12/P12-1 -> 0.38812785 | R12: All cash | S12: Operational improvement in industrial equipment and aftermarket. | T12: S27 / S28 / S29 | U12: Core — both | V12: =COUNTIFS($B$6:$B$13,B12,$C$6:$C$13,C12) -> 1 | W12: =IF(ABS(M12-H12/J12)<0.0001,"PASS","REVIEW") -> PASS | X12: =IF(ISNUMBER(SEARCH("implied by disclosed",L12)),"DERIVED — DISCLOSED MULTIPLE",IF(ABS(N12-H12/K12)<0.0001,"PASS","REVIEW")) -> DERIVED — DISCLOSED MULTIPLE | Y12: PASS | Z12: Industrial compressors / engineered equipment
A13: 8 | B13: Caterpillar | C13: Bucyrus | D13: 40497 | E13: Completed — 08-Jul-2011 | F13: Public strategic | G13: 7600 | H13: 8609 | I13: FY2010A | J13: 3650.563 | K13: 720.647 | L13: Adjusted EBITDA | M13: =H13/J13 -> 2.3582664 | N13: =H13/K13 -> 11.946209 | O13: 92 | P13: 69.697 | Q13: =O13/P13-1 -> 0.31999943 | R13: All cash | S13: Mining-equipment scale, complementary products and aftermarket. | T13: S30 / S31 | U13: Core — both | V13: =COUNTIFS($B$6:$B$13,B13,$C$6:$C$13,C13) -> 1 | W13: =IF(ABS(M13-H13/J13)<0.0001,"PASS","REVIEW") -> PASS | X13: =IF(ISNUMBER(SEARCH("implied by disclosed",L13)),"DERIVED — DISCLOSED MULTIPLE",IF(ABS(N13-H13/K13)<0.0001,"PASS","REVIEW")) -> PASS | Y13: PASS | Z13: Mining equipment / engineered products
A16: SUPPLEMENTAL REFERENCE TRANSACTIONS — EXCLUDED WHERE DATA / PERIOD IS INCOMPLETE
A17: # | B17: Buyer | C17: Target | D17: Announcement | E17: Completion / Status | F17: Transaction Type | G17: Equity Value | H17: Enterprise Value | I17: Financial Period | J17: Revenue | K17: EBITDA | L17: EBITDA Basis | M17: EV / Revenue | N17: EV / EBITDA | O17: Offer Price | P17: Unaffected Price | Q17: Premium | R17: Consideration | S17: Strategic Rationale | T17: Source ID | U17: Statistical Inclusion | V17: Duplicate Count | W17: EV / Revenue Check | X17: =IF(ISNUMBER(SEARCH("implied by disclosed",L17)),"DERIVED — DISCLOSED MULTIPLE","NOT APPLICABLE — SUPPLEMENTAL") -> NOT APPLICABLE — SUPPLEMENTAL | Y17: Units Check | Z17: Industry
A18: 9 | B18: Honeywell | C18: Sundyne | D18: 45720 | E18: Completed — 06-Jun-2025 | F18: Private strategic | G18: Not disclosed | H18: 2160 | I18: FY2024A | J18: Not disclosed | K18: 148.966 | L18: EBITDA implied by disclosed 14.5x | M18: Not disclosed | N18: 14.5 | O18: Not disclosed | P18: Not disclosed | Q18: Not disclosed | R18: All cash | S18: Critical pumps and compressors for refining, petrochemicals and LNG. | T18: S32 | U18: Supplemental — EV/EBITDA only; revenue not disclosed | V18: Not applicable — supplemental | W18: Not applicable — supplemental | X18: =IF(ISNUMBER(SEARCH("implied by disclosed",L18)),"DERIVED — FORWARD MULTIPLE","NOT APPLICABLE — SUPPLEMENTAL") -> DERIVED — FORWARD MULTIPLE | Y18: PASS | Z18: Critical pumps / compressors
A19: 10 | B19: GE | C19: Lufkin Industries | D19: 41372 | E19: Completed — 01-Jul-2013 | F19: Public strategic | G19: Not disclosed | H19: 3300 | I19: FY2012A revenue / 2013E EBITDA | J19: 1300 | K19: 244.444 | L19: Forward EBITDA implied by disclosed 13.5x | M19: 2.538 | N19: 13.5 | O19: Not disclosed | P19: Not disclosed | Q19: Not disclosed | R19: All cash | S19: Artificial lift and oilfield production equipment. | T19: S33 | U19: Supplemental — forward / mismatched period | V19: Not applicable — supplemental | W19: Not applicable — supplemental | X19: Not applicable — supplemental | Y19: PASS | Z19: Oilfield equipment / artificial lift
A22: COMPARABILITY SCREENING
A23: Transaction | B23: Industry Similarity (1-5) | C23: Business Model (1-5) | D23: Size (1-5) | E23: Strategic Rationale (1-5) | F23: Recency (1-5) | G23: Data Availability (1-5) | H23: Total / 30 | I23: Screening Comment
A24: Flowserve / Velan | B24: 5 | C24: 5 | D24: 2 | E24: 5 | F24: 5 | G24: 5 | H24: =SUM(B24:G24) -> 27 | I24: Very strong product similarity; smaller and terminated.
A25: SLB / ChampionX | B25: 4 | C25: 4 | D25: 5 | E25: 5 | F25: 5 | G25: 5 | H25: =SUM(B25:G25) -> 28 | I25: Large, recent energy-services transaction.
A26: Emerson / NI | B26: 4 | C26: 4 | D26: 5 | E26: 4 | F26: 5 | G26: 5 | H26: =SUM(B26:G26) -> 27 | I26: High-quality industrial technology reference; premium software mix.
A27: Regal Rexnord / Altra | B27: 4 | C27: 5 | D27: 4 | E27: 5 | F27: 5 | G27: 5 | H27: =SUM(B27:G27) -> 28 | I27: Strong engineered-products and motion-control relevance.
A28: Chart / Howden | B28: 5 | C28: 5 | D28: 4 | E28: 5 | F28: 5 | G28: 5 | H28: =SUM(B28:G28) -> 29 | I28: Direct strategic and business-model relevance.
A29: Siemens / Dresser-Rand | B29: 5 | C29: 5 | D29: 5 | E29: 5 | F29: 2 | G29: 5 | H29: =SUM(B29:G29) -> 27 | I29: Highly relevant rotating-equipment transaction; older.
A30: KKR / Gardner Denver | B30: 4 | C30: 5 | D30: 4 | E30: 4 | F30: 1 | G30: 5 | H30: =SUM(B30:G30) -> 23 | I30: Strong industrial-equipment relevance; sponsor and older.
A31: Caterpillar / Bucyrus | B31: 4 | C31: 4 | D31: 5 | E31: 5 | F31: 1 | G31: 5 | H31: =SUM(B31:G31) -> 24 | I31: Large engineered-equipment reference; older.
A34: Core inclusion requires verified enterprise value, revenue, EBITDA and a comparable financial period. EBITDA Basis is disclosed explicitly for every observation; “Not disclosed” is used where public documents do not support a value. Supplemental references remain excluded from affected statistics for missing or mismatched data—not to manage the resulting median.
A35: Core inclusion requires verified enterprise value, revenue, EBITDA and a comparable period. Emerson / National Instruments is retained but specifically flagged: its 30.6x EV / EBITDA uses standardized EBITDA (EBIT + D&A) and is not directly comparable to operating-heavy observations. Altra and Gardner Denver EBITDA are derived from disclosed multiples; Sundyne is derived and supplemental.

Sheet Transaction Multiples
A1: TRANSACTION MULTIPLES AND PTA STATISTICS
A2: Core statistical set only | Historical periods shown in source table | Invalid or incomplete observations excluded
A4: CORE MULTIPLE OBSERVATIONS
A5: Transaction | B5: EV / Revenue | C5: EV / EBITDA | D5: Premium | E5: Financial Period | F5: Status
A6: ='Precedent Transactions'!B6&" / "&'Precedent Transactions'!C6 -> Flowserve / Velan | B6: ='Precedent Transactions'!M6 -> 0.64473684 | C6: ='Precedent Transactions'!N6 -> 11.666667 | D6: ='Precedent Transactions'!Q6 -> 1 | E6: ='Precedent Transactions'!I6 -> LTM Nov-2022 | F6: Included — core
A7: ='Precedent Transactions'!B7&" / "&'Precedent Transactions'!C7 -> SLB / ChampionX | B7: ='Precedent Transactions'!M7 -> 2.1314179 | C7: ='Precedent Transactions'!N7 -> 10.388721 | D7: ='Precedent Transactions'!Q7 -> 0.147 | E7: ='Precedent Transactions'!I7 -> FY2023A | F7: Included — core
A8: ='Precedent Transactions'!B8&" / "&'Precedent Transactions'!C8 -> Emerson / National Instruments | B8: ='Precedent Transactions'!M8 -> 5.2221669 | C8: ='Precedent Transactions'!N8 -> 30.600192 | D8: ='Precedent Transactions'!Q8 -> 0.49365198 | E8: ='Precedent Transactions'!I8 -> FY2022A | F8: Included — core
A9: ='Precedent Transactions'!B9&" / "&'Precedent Transactions'!C9 -> Regal Rexnord / Altra Industrial Motion | B9: ='Precedent Transactions'!M9 -> 2.5438101 | C9: ='Precedent Transactions'!N9 -> 13.6 | D9: ='Precedent Transactions'!Q9 -> 0.54000154 | E9: ='Precedent Transactions'!I9 -> LTM Sep-2022 | F9: Included — core
A10: ='Precedent Transactions'!B10&" / "&'Precedent Transactions'!C10 -> Chart Industries / Howden | B10: ='Precedent Transactions'!M10 -> 2.4471667 | C10: ='Precedent Transactions'!N10 -> 13.148955 | D10: ='Precedent Transactions'!Q10 -> Not disclosed | E10: ='Precedent Transactions'!I10 -> LTM Aug/Sep-2022 | F10: Included — core
A11: ='Precedent Transactions'!B11&" / "&'Precedent Transactions'!C11 -> Siemens / Dresser-Rand | B11: ='Precedent Transactions'!M11 -> 2.5796028 | C11: ='Precedent Transactions'!N11 -> 10.961749 | D11: ='Precedent Transactions'!Q11 -> Not disclosed | E11: ='Precedent Transactions'!I11 -> FY2013A | F11: Included — core
A12: ='Precedent Transactions'!B12&" / "&'Precedent Transactions'!C12 -> KKR / Gardner Denver | B12: ='Precedent Transactions'!M12 -> 1.6525424 | C12: ='Precedent Transactions'!N12 -> 8.3000003 | D12: ='Precedent Transactions'!Q12 -> 0.38812785 | E12: ='Precedent Transactions'!I12 -> FY2012A | F12: Included — core
A13: ='Precedent Transactions'!B13&" / "&'Precedent Transactions'!C13 -> Caterpillar / Bucyrus | B13: ='Precedent Transactions'!M13 -> 2.3582664 | C13: ='Precedent Transactions'!N13 -> 11.946209 | D13: ='Precedent Transactions'!Q13 -> 0.31999943 | E13: ='Precedent Transactions'!I13 -> FY2010A | F13: Included — core
A16: VALID PREMIUM OBSERVATIONS — NUMERIC VALUES ONLY | G16: MULTIPLE DISTRIBUTION — CORE HISTORICAL SET
A17: Transaction | B17: Premium | C17: Eligibility Note | G17: Metric | H17: Minimum | I17: 25th | J17: Median | K17: 75th | L17: Maximum
A18: Flowserve / Velan | B18: ='Precedent Transactions'!Q6 -> 1 | C18: Verified unaffected price / disclosed premium | G18: EV / Revenue | H18: =$B$28 -> 0.64473684 | I18: =$B$29 -> 2.011699 | J18: =$B$30 -> 2.4027165 | K18: =$B$31 -> 2.5527582 | L18: =$B$32 -> 5.2221669
A19: SLB / ChampionX | B19: ='Precedent Transactions'!Q7 -> 0.147 | C19: Verified unaffected price / disclosed premium | G19: EV / EBITDA | H19: =$C$28 -> 8.3000003 | I19: =$C$29 -> 10.818492 | J19: =$C$30 -> 11.806438 | K19: =$C$31 -> 13.261716 | L19: =$C$32 -> 30.600192
A20: Emerson / NI | B20: ='Precedent Transactions'!Q8 -> 0.49365198 | C20: Verified unaffected price / disclosed premium
A21: Regal Rexnord / Altra | B21: ='Precedent Transactions'!Q9 -> 0.54000154 | C21: Verified unaffected price / disclosed premium | G21: SELECTED PTA MULTIPLES
A22: KKR / Gardner Denver | B22: ='Precedent Transactions'!Q12 -> 0.38812785 | C22: Verified unaffected price / disclosed premium | G22: Metric | H22: Selected Multiple | I22: Selection Basis | J22: Rationale
A23: Caterpillar / Bucyrus | B23: ='Precedent Transactions'!Q13 -> 0.31999943 | C23: Verified unaffected price / disclosed premium | G23: EV / Revenue | H23: =$B$30 -> 2.4027165 | I23: Median | J23: Core historical median; percentile valuation range retained
G24: EV / EBITDA | H24: =$C$30 -> 11.806438 | I24: Median | J24: Core historical median; explicit EBITDA-basis disclosure retained
A26: STATISTICAL SUMMARY — VALID OBSERVATIONS ONLY | G26: Selected multiples use the median of the eight verified core historical transactions. Different EBITDA bases are not silently standardized: each basis is disclosed in the Precedent Transactions tab, and the percentile range limits reliance on individual extremes.
A27: Statistic | B27: EV / Revenue | C27: EV / EBITDA | D27: Premium
A28: Minimum | B28: =MIN(B6:B13) -> 0.64473684 | C28: =MIN(C6:C13) -> 8.3000003 | D28: =MIN(B18:B23) -> 0.147
A29: 25th Percentile | B29: =_xlfn.PERCENTILE.INC(B6:B13,0.25) -> 2.011699 | C29: =_xlfn.PERCENTILE.INC(C6:C13,0.25) -> 10.818492 | D29: =_xlfn.PERCENTILE.INC(B18:B23,0.25) -> 0.33703153 | G29: SECONDARY SENSITIVITIES
A30: Median | B30: =MEDIAN(B6:B13) -> 2.4027165 | C30: =MEDIAN(C6:C13) -> 11.806438 | D30: =MEDIAN(B18:B23) -> 0.44088992 | G30: Metric | H30: Full Core | I30: Ex-NI | J30: Recent Only (2020+)
A31: 75th Percentile | B31: =_xlfn.PERCENTILE.INC(B6:B13,0.75) -> 2.5527582 | C31: =_xlfn.PERCENTILE.INC(C6:C13,0.75) -> 13.261716 | D31: =_xlfn.PERCENTILE.INC(B18:B23,0.75) -> 0.52841415 | G31: Median EV / Revenue | H31: =B30 -> 2.4027165 | I31: =MEDIAN(B6:B7,B9:B13) -> 2.3582664 | J31: =MEDIAN(B6:B10) -> 2.4471667
A32: Maximum | B32: =MAX(B6:B13) -> 5.2221669 | C32: =MAX(C6:C13) -> 30.600192 | D32: =MAX(B18:B23) -> 1 | G32: Median EV / EBITDA | H32: =C30 -> 11.806438 | I32: =MEDIAN(C6:C7,C9:C13) -> 11.666667 | J32: =MEDIAN(C6:C10) -> 13.148955
A33: Mean | B33: =AVERAGE(B6:B13) -> 2.4474637 | C33: =AVERAGE(C6:C13) -> 13.826562 | D33: =AVERAGE(B18:B23) -> 0.48146347 | G33: Mean EV / EBITDA | H33: =C33 -> 13.826562 | I33: =AVERAGE(C6:C7,C9:C13) -> 11.430329 | J33: =AVERAGE(C6:C10) -> 15.880907
G34: Observation Count | H34: =COUNT(C6:C13) -> 8 | I34: =COUNT(C6:C7,C9:C13) -> 7 | J34: =COUNT(C6:C10) -> 5
A36: Premium statistics use only the six transactions with a verified unaffected price or a directly disclosed premium. Private targets and transactions without a reliable pre-announcement price are explicitly excluded. The focal Baker Hughes / Chart transaction and supplemental references are not included in these precedent statistics.
A39: ="Emerson / National Instruments uses standardized EBITDA (EBIT + D&A) and produces "&TEXT(C8,"0.0x")&", versus a full-set median of "&TEXT(C30,"0.0x")&" and an ex-NI median of "&TEXT(I32,"0.0x")&". It is retained in the raw set but does not set the percentile-based football-field range." -> Emerson / National Instruments uses standardized EBITDA (EBIT + D&A) and produces 30.6x, versus a full-set median of 11.8x and an ex-NI median of 11.7x. It is retained in the raw set but does not set the percentile-based football-field range.

Sheet Premium Analysis
A1: PREMIUM ANALYSIS
A2: Offer price vs. unaffected share price | Verified observations only
A4: FOCAL TRANSACTION PREMIUM | F4: Transaction | G4: Premium (%)
A5: Metric | B5: Value | C5: Basis | F5: Baker Hughes / Chart | G5: =$B$8*100 -> 22.341975
A6: Offer Price / Share | B6: ='Transaction Overview'!B10 -> 210 | C6: Reported | F6: Flowserve / Velan | G6: =$D12*100 -> 100
A7: Unaffected Share Price | B7: ='Transaction Overview'!B11 -> 171.65 | C7: 28-Jul-2025 close | F7: SLB / ChampionX | G7: =$D13*100 -> 14.7
A8: Baker Hughes / Chart Premium | B8: ='Transaction Overview'!B12 -> 0.22341975 | C8: Calculated | F8: Emerson / NI | G8: =$D14*100 -> 49.365198
F9: Regal Rexnord / Altra | G9: =$D15*100 -> 54.000154
A10: PRECEDENT TRANSACTION PREMIUMS — VERIFIED OBSERVATIONS | F10: KKR / Gardner Denver | G10: =$D16*100 -> 38.812785
A11: Transaction | B11: Offer Price | C11: Unaffected Price | D11: Premium | F11: Caterpillar / Bucyrus | G11: =$D17*100 -> 31.999943
A12: Flowserve / Velan | B12: ='Precedent Transactions'!O6 -> 13 | C12: ='Precedent Transactions'!P6 -> 6.5 | D12: ='Precedent Transactions'!Q6 -> 1
A13: SLB / ChampionX | B13: ='Precedent Transactions'!O7 -> Not disclosed | C13: ='Precedent Transactions'!P7 -> Not disclosed | D13: ='Precedent Transactions'!Q7 -> 0.147
A14: Emerson / NI | B14: ='Precedent Transactions'!O8 -> 60 | C14: ='Precedent Transactions'!P8 -> 40.17 | D14: ='Precedent Transactions'!Q8 -> 0.49365198
A15: Regal Rexnord / Altra | B15: ='Precedent Transactions'!O9 -> 62 | C15: ='Precedent Transactions'!P9 -> 40.2597 | D15: ='Precedent Transactions'!Q9 -> 0.54000154
A16: KKR / Gardner Denver | B16: ='Precedent Transactions'!O12 -> 76 | C16: ='Precedent Transactions'!P12 -> 54.75 | D16: ='Precedent Transactions'!Q12 -> 0.38812785
A17: Caterpillar / Bucyrus | B17: ='Precedent Transactions'!O13 -> 92 | C17: ='Precedent Transactions'!P13 -> 69.697 | D17: ='Precedent Transactions'!Q13 -> 0.31999943
A19: PREMIUM STATISTICS — VERIFIED OBSERVATIONS
A20: Statistic | B20: Premium
A21: Minimum | B21: =MIN(D12:D17) -> 0.147
A22: 25th Percentile | B22: =_xlfn.PERCENTILE.INC(D12:D17,0.25) -> 0.33703153
A23: Median | B23: =MEDIAN(D12:D17) -> 0.44088992
A24: 75th Percentile | B24: =_xlfn.PERCENTILE.INC(D12:D17,0.75) -> 0.52841415
A25: Maximum | B25: =MAX(D12:D17) -> 1
A26: Mean | B26: =AVERAGE(D12:D17) -> 0.48146347
A28: FOCAL PREMIUM VS. PRECEDENT RANGE
A29: Comparison | B29: Result
A30: Premium / (Discount) to Precedent Median | B30: =B8-B23 -> -0.21747017
A31: Baker Hughes / Chart Premium within Precedent 25th–75th Range? | B31: =IF(AND(B8>=B22,B8<=B24),"YES","NO") -> NO | F31: Flowserve / Velan’s 100.0% premium is retained because it is supported by the transaction announcement. It is an outlier relative to the rest of the verified set, so the median and percentile statistics are emphasized alongside the mean.
A33: Premium statistics use only the six precedent transactions with a verified unaffected price or a directly disclosed premium, consistent with the Transaction Multiples tab. Private targets and transactions lacking a reliable pre-announcement price are excluded.

Sheet PTA Valuation
A1: CHART INDUSTRIES — PRECEDENT TRANSACTIONS VALUATION
A2: Selected range uses 25th percentile / median / 75th percentile; $ in millions except per share
A4: VALUATION INPUTS
A5: Input | B5: Value | C5: Basis | D5: Source
A6: FY2024A Revenue | B6: ='Target Financials'!B24 -> 4160.3 | C6: Reported actual | D6: S05
A7: FY2024A Adjusted EBITDA | B7: ='Target Financials'!B25 -> 1013.8 | C7: Reported non-GAAP | D7: S05
A8: FY2024A Net Debt | B8: ='Target Financials'!B26 -> 3333 | C8: Debt less cash | D8: S05
A9: Diluted Shares | B9: ='Target Financials'!B27 -> 49.025963 | C9: Signing-date fully diluted share equivalents | D9: S09
A10: Unaffected Share Price | B10: ='Target Financials'!B28 -> 171.65 | C10: 28-Jul-2025 close | D10: S03
A11: Offer Price | B11: ='Target Financials'!B29 -> 210 | C11: Cash consideration | D11: S01
A14: EV / REVENUE METHOD
A15: Metric | B15: Low — 25th | C15: Median | D15: High — 75th | F15: Selected Multiple | G15: Implied EV | H15: Implied Equity Value | I15: Implied Share Price | J15: Premium / (Discount) vs Offer | K15: Less: Net Debt | L15: Diluted Shares | M15: Premium / (Discount) vs Unaffected
A16: EV / Revenue Multiple | B16: ='Transaction Multiples'!B29 -> 2.011699 | C16: ='Transaction Multiples'!B30 -> 2.4027165 | D16: ='Transaction Multiples'!B31 -> 2.5527582
A17: Low | F17: =B16 -> 2.011699 | G17: =$B$6*F17 -> 8369.2715 | H17: =G17-$B$8 -> 5036.2715 | I17: =H17/$B$9 -> 102.72662 | J17: =I17/$B$11-1 -> -0.51082561 | K17: =-$B$8 -> -3333 | L17: =$B$9 -> 49.025963 | M17: =I17/$B$10-1 -> -0.40153439
A18: Median | F18: =C16 -> 2.4027165 | G18: =$B$6*F18 -> 9996.0216 | H18: =G18-$B$8 -> 6663.0216 | I18: =H18/$B$9 -> 135.90802 | J18: =I18/$B$11-1 -> -0.35281895 | K18: =-$B$8 -> -3333 | L18: =$B$9 -> 49.025963 | M18: =I18/$B$10-1 -> -0.20822592
A19: High | F19: =D16 -> 2.5527582 | G19: =$B$6*F19 -> 10620.24 | H19: =G19-$B$8 -> 7287.2401 | I19: =H19/$B$9 -> 148.64043 | J19: =I19/$B$11-1 -> -0.29218843 | K19: =-$B$8 -> -3333 | L19: =$B$9 -> 49.025963 | M19: =I19/$B$10-1 -> -0.13404935
A22: EV / ADJUSTED EBITDA METHOD
A23: Metric | B23: Low — 25th | C23: Median | D23: High — 75th | F23: Selected Multiple | G23: Implied EV | H23: Implied Equity Value | I23: Implied Share Price | J23: Premium / (Discount) vs Offer | K23: Less: Net Debt | L23: Diluted Shares | M23: Premium / (Discount) vs Unaffected
A24: EV / EBITDA Multiple | B24: ='Transaction Multiples'!C29 -> 10.818492 | C24: ='Transaction Multiples'!C30 -> 11.806438 | D24: ='Transaction Multiples'!C31 -> 13.261716
A25: Low | F25: =B24 -> 10.818492 | G25: =$B$7*F25 -> 10967.787 | H25: =G25-$B$8 -> 7634.7875 | I25: =H25/$B$9 -> 155.72947 | J25: =I25/$B$11-1 -> -0.25843107 | K25: =-$B$8 -> -3333 | L25: =$B$9 -> 49.025963 | M25: =I25/$B$10-1 -> -0.092749927
A26: Median | F26: =C24 -> 11.806438 | G26: =$B$7*F26 -> 11969.367 | H26: =G26-$B$8 -> 8636.3669 | I26: =H26/$B$9 -> 176.15905 | J26: =I26/$B$11-1 -> -0.16114739 | K26: =-$B$8 -> -3333 | L26: =$B$9 -> 49.025963 | M26: =I26/$B$10-1 -> 0.026268844
A27: High | F27: =D24 -> 13.261716 | G27: =$B$7*F27 -> 13444.728 | H27: =G27-$B$8 -> 10111.728 | I27: =H27/$B$9 -> 206.25251 | J27: =I27/$B$11-1 -> -0.017845181 | K27: =-$B$8 -> -3333 | L27: =$B$9 -> 49.025963 | M27: =I27/$B$10-1 -> 0.2015876
A30: VALUATION SUMMARY
A31: Method / Output | B31: EV/Revenue Low | C31: EV/Revenue Median | D31: EV/Revenue High | E31: EV/EBITDA Low | F31: EV/EBITDA Median | G31: EV/EBITDA High | H31: Blended Low | I31: Blended Median | J31: Blended High
A32: Implied Enterprise Value | B32: =G17 -> 8369.2715 | C32: =G18 -> 9996.0216 | D32: =G19 -> 10620.24 | E32: =G25 -> 10967.787 | F32: =G26 -> 11969.367 | G32: =G27 -> 13444.728 | H32: =AVERAGE(B32,E32) -> 9668.5295 | I32: =AVERAGE(C32,F32) -> 10982.694 | J32: =AVERAGE(D32,G32) -> 12032.484
A33: Implied Equity Value | B33: =H17 -> 5036.2715 | C33: =H18 -> 6663.0216 | D33: =H19 -> 7287.2401 | E33: =H25 -> 7634.7875 | F33: =H26 -> 8636.3669 | G33: =H27 -> 10111.728 | H33: =AVERAGE(B33,E33) -> 6335.5295 | I33: =AVERAGE(C33,F33) -> 7649.6942 | J33: =AVERAGE(D33,G33) -> 8699.4841
A34: Implied Share Price | B34: =I17 -> 102.72662 | C34: =I18 -> 135.90802 | D34: =I19 -> 148.64043 | E34: =I25 -> 155.72947 | F34: =I26 -> 176.15905 | G34: =I27 -> 206.25251 | H34: =AVERAGE(B34,E34) -> 129.22805 | I34: =AVERAGE(C34,F34) -> 156.03353 | J34: =AVERAGE(D34,G34) -> 177.44647
A35: Premium / (Discount) to Unaffected | B35: =B34/$B$10-1 -> -0.40153439 | C35: =C34/$B$10-1 -> -0.20822592 | D35: =D34/$B$10-1 -> -0.13404935 | E35: =E34/$B$10-1 -> -0.092749927 | F35: =F34/$B$10-1 -> 0.026268844 | G35: =G34/$B$10-1 -> 0.2015876 | H35: =AVERAGE(B35,E35) -> -0.24714216 | I35: =AVERAGE(C35,F35) -> -0.090978539 | J35: =AVERAGE(D35,G35) -> 0.033769125
A36: Premium / (Discount) to Offer | B36: =B34/$B$11-1 -> -0.51082561 | C36: =C34/$B$11-1 -> -0.35281895 | D36: =D34/$B$11-1 -> -0.29218843 | E36: =E34/$B$11-1 -> -0.25843107 | F36: =F34/$B$11-1 -> -0.16114739 | G36: =G34/$B$11-1 -> -0.017845181 | H36: =AVERAGE(B36,E36) -> -0.38462834 | I36: =AVERAGE(C36,F36) -> -0.25698317 | J36: =AVERAGE(D36,G36) -> -0.15501681
A39: Selected Base Case | B39: Value | C39: Definition | D39: Conclusion
A40: Blended Median Implied Share Price | B40: =I34 -> 156.03353 | C40: Average of EV/Revenue and EV/EBITDA median implied share prices | D40: Selected PTA base case
A41: Premium / (Discount) to Unaffected | B41: =B40/$B$10-1 -> -0.090978539 | C41: Selected value / $171.65 - 1 | D41: Illustrative
A42: Premium / (Discount) to Offer | B42: =B40/$B$11-1 -> -0.25698317 | C42: Selected value / $210.00 - 1 | D42: Illustrative
A45: Valuation interpretation: percentile-based ranges reduce the influence of extreme observations. The selected base case is the simple average of the two median implied share prices; it is an analyst selection, not a company-disclosed value or fairness opinion.

Sheet Sensitivity Analysis
A1: SENSITIVITY ANALYSIS — IMPLIED SHARE PRICE
A2: Implied share price sensitivity to EV/Revenue and EV/EBITDA multiples | $ per share
A4: BASE INPUTS
A5: Input | B5: Value | C5: Source
A6: FY2024A Revenue | B6: ='PTA Valuation'!B6 -> 4160.3 | C6: Target Financials
A7: FY2024A Adjusted EBITDA | B7: ='PTA Valuation'!B7 -> 1013.8 | C7: Target Financials
A8: FY2024A Net Debt | B8: ='PTA Valuation'!B8 -> 3333 | C8: Target Financials
A9: Diluted Shares | B9: ='PTA Valuation'!B9 -> 49.025963 | C9: Target Financials
A10: Offer Price / Share | B10: ='PTA Valuation'!B11 -> 210 | C10: Transaction Overview
A12: EV / REVENUE SENSITIVITY — IMPLIED SHARE PRICE
A13: EV / Revenue Multiple | F13: ='Transaction Multiples'!B30 -> 2.4027165
A14: Multiple | B14: Implied EV | C14: Implied Equity Value | D14: Implied Share Price | E14: Premium / (Discount) to Offer | F14: Scenario
A15: =$F$13+(-0.5) -> 1.9027165 | B15: =$B$6*A15 -> 7915.8716 | C15: =B15-$B$8 -> 4582.8716 | D15: =C15/$B$9 -> 93.478461 | E15: =D15/$B$10-1 -> -0.55486447 | F15: Downside
A16: =$F$13+(-0.25) -> 2.1527165 | B16: =$B$6*A16 -> 8955.9466 | C16: =B16-$B$8 -> 5622.9466 | D16: =C16/$B$9 -> 114.69324 | E16: =D16/$B$10-1 -> -0.45384171 | F16: Downside
A17: =$F$13+(0) -> 2.4027165 | B17: =$B$6*A17 -> 9996.0216 | C17: =B17-$B$8 -> 6663.0216 | D17: =C17/$B$9 -> 135.90802 | E17: =D17/$B$10-1 -> -0.35281895 | F17: Base Case
A18: =$F$13+(0.25) -> 2.6527165 | B18: =$B$6*A18 -> 11036.097 | C18: =B18-$B$8 -> 7703.0966 | D18: =C18/$B$9 -> 157.1228 | E18: =D18/$B$10-1 -> -0.25179619 | F18: Upside
A19: =$F$13+(0.5) -> 2.9027165 | B19: =$B$6*A19 -> 12076.172 | C19: =B19-$B$8 -> 8743.1716 | D19: =C19/$B$9 -> 178.33758 | E19: =D19/$B$10-1 -> -0.15077343 | F19: Upside
A21: EV / EBITDA SENSITIVITY — IMPLIED SHARE PRICE
A22: EV / EBITDA Multiple | F22: ='Transaction Multiples'!C30 -> 11.806438
A23: Multiple | B23: Implied EV | C23: Implied Equity Value | D23: Implied Share Price | E23: Premium / (Discount) to Offer | F23: Scenario
A24: =$F$22+(-0.5) -> 11.306438 | B24: =$B$7*A24 -> 11462.467 | C24: =B24-$B$8 -> 8129.4669 | D24: =C24/$B$9 -> 165.81963 | E24: =D24/$B$10-1 -> -0.21038273 | F24: Downside
A25: =$F$22+(-0.25) -> 11.556438 | B25: =$B$7*A25 -> 11715.917 | C25: =B25-$B$8 -> 8382.9169 | D25: =C25/$B$9 -> 170.98934 | E25: =D25/$B$10-1 -> -0.18576506 | F25: Downside
A26: =$F$22+(0) -> 11.806438 | B26: =$B$7*A26 -> 11969.367 | C26: =B26-$B$8 -> 8636.3669 | D26: =C26/$B$9 -> 176.15905 | E26: =D26/$B$10-1 -> -0.16114739 | F26: Base Case
A27: =$F$22+(0.25) -> 12.056438 | B27: =$B$7*A27 -> 12222.817 | C27: =B27-$B$8 -> 8889.8169 | D27: =C27/$B$9 -> 181.32876 | E27: =D27/$B$10-1 -> -0.13652973 | F27: Upside
A28: =$F$22+(0.5) -> 12.306438 | B28: =$B$7*A28 -> 12476.267 | C28: =B28-$B$8 -> 9143.2669 | D28: =C28/$B$9 -> 186.49847 | E28: =D28/$B$10-1 -> -0.11191206 | F28: Upside
A30: TWO-WAY SENSITIVITY — BLENDED IMPLIED SHARE PRICE ($/SHARE)
A31: Rows: EV/EBITDA multiple (down) | Columns: EV/Revenue multiple (across) — blended average implied share price
A32: EV/EBITDA \ EV/Rev | B32: =$F$13+(-0.5) -> 1.9027165 | C32: =$F$13+(-0.25) -> 2.1527165 | D32: =$F$13+(0) -> 2.4027165 | E32: =$F$13+(0.25) -> 2.6527165 | F32: =$F$13+(0.5) -> 2.9027165
A33: =$F$22+(-0.5) -> 11.306438 | B33: =AVERAGE(((($B$6*($F$13+(-0.5)))-$B$8)/$B$9),((($B$7*($F$22+(-0.5)))-$B$8)/$B$9)) -> 129.64904 | C33: =AVERAGE(((($B$6*($F$13+(-0.25)))-$B$8)/$B$9),((($B$7*($F$22+(-0.5)))-$B$8)/$B$9)) -> 140.25643 | D33: =AVERAGE(((($B$6*($F$13+(0)))-$B$8)/$B$9),((($B$7*($F$22+(-0.5)))-$B$8)/$B$9)) -> 150.86382 | E33: =AVERAGE(((($B$6*($F$13+(0.25)))-$B$8)/$B$9),((($B$7*($F$22+(-0.5)))-$B$8)/$B$9)) -> 161.47121 | F33: =AVERAGE(((($B$6*($F$13+(0.5)))-$B$8)/$B$9),((($B$7*($F$22+(-0.5)))-$B$8)/$B$9)) -> 172.0786
A34: =$F$22+(-0.25) -> 11.556438 | B34: =AVERAGE(((($B$6*($F$13+(-0.5)))-$B$8)/$B$9),((($B$7*($F$22+(-0.25)))-$B$8)/$B$9)) -> 132.2339 | C34: =AVERAGE(((($B$6*($F$13+(-0.25)))-$B$8)/$B$9),((($B$7*($F$22+(-0.25)))-$B$8)/$B$9)) -> 142.84129 | D34: =AVERAGE(((($B$6*($F$13+(0)))-$B$8)/$B$9),((($B$7*($F$22+(-0.25)))-$B$8)/$B$9)) -> 153.44868 | E34: =AVERAGE(((($B$6*($F$13+(0.25)))-$B$8)/$B$9),((($B$7*($F$22+(-0.25)))-$B$8)/$B$9)) -> 164.05607 | F34: =AVERAGE(((($B$6*($F$13+(0.5)))-$B$8)/$B$9),((($B$7*($F$22+(-0.25)))-$B$8)/$B$9)) -> 174.66346
A35: =$F$22+(0) -> 11.806438 | B35: =AVERAGE(((($B$6*($F$13+(-0.5)))-$B$8)/$B$9),((($B$7*($F$22+(0)))-$B$8)/$B$9)) -> 134.81875 | C35: =AVERAGE(((($B$6*($F$13+(-0.25)))-$B$8)/$B$9),((($B$7*($F$22+(0)))-$B$8)/$B$9)) -> 145.42614 | D35: =AVERAGE(((($B$6*($F$13+(0)))-$B$8)/$B$9),((($B$7*($F$22+(0)))-$B$8)/$B$9)) -> 156.03353 | E35: =AVERAGE(((($B$6*($F$13+(0.25)))-$B$8)/$B$9),((($B$7*($F$22+(0)))-$B$8)/$B$9)) -> 166.64092 | F35: =AVERAGE(((($B$6*($F$13+(0.5)))-$B$8)/$B$9),((($B$7*($F$22+(0)))-$B$8)/$B$9)) -> 177.24831
A36: =$F$22+(0.25) -> 12.056438 | B36: =AVERAGE(((($B$6*($F$13+(-0.5)))-$B$8)/$B$9),((($B$7*($F$22+(0.25)))-$B$8)/$B$9)) -> 137.40361 | C36: =AVERAGE(((($B$6*($F$13+(-0.25)))-$B$8)/$B$9),((($B$7*($F$22+(0.25)))-$B$8)/$B$9)) -> 148.011 | D36: =AVERAGE(((($B$6*($F$13+(0)))-$B$8)/$B$9),((($B$7*($F$22+(0.25)))-$B$8)/$B$9)) -> 158.61839 | E36: =AVERAGE(((($B$6*($F$13+(0.25)))-$B$8)/$B$9),((($B$7*($F$22+(0.25)))-$B$8)/$B$9)) -> 169.22578 | F36: =AVERAGE(((($B$6*($F$13+(0.5)))-$B$8)/$B$9),((($B$7*($F$22+(0.25)))-$B$8)/$B$9)) -> 179.83317
A37: =$F$22+(0.5) -> 12.306438 | B37: =AVERAGE(((($B$6*($F$13+(-0.5)))-$B$8)/$B$9),((($B$7*($F$22+(0.5)))-$B$8)/$B$9)) -> 139.98846 | C37: =AVERAGE(((($B$6*($F$13+(-0.25)))-$B$8)/$B$9),((($B$7*($F$22+(0.5)))-$B$8)/$B$9)) -> 150.59585 | D37: =AVERAGE(((($B$6*($F$13+(0)))-$B$8)/$B$9),((($B$7*($F$22+(0.5)))-$B$8)/$B$9)) -> 161.20324 | E37: =AVERAGE(((($B$6*($F$13+(0.25)))-$B$8)/$B$9),((($B$7*($F$22+(0.5)))-$B$8)/$B$9)) -> 171.81063 | F37: =AVERAGE(((($B$6*($F$13+(0.5)))-$B$8)/$B$9),((($B$7*($F$22+(0.5)))-$B$8)/$B$9)) -> 182.41802
A39: Sensitivity ranges are centered on the median EV/Revenue and EV/EBITDA precedent multiples from the Transaction Multiples tab, stepped in 0.25x increments. The two-way grid shows the simple average of the EV/Revenue-implied and EV/EBITDA-implied share prices at each multiple pairing.
A41: SENSITIVITY INTERPRETATION
A42: Scenario | B42: Implied Share Price | C42: Definition
A43: Downside | B43: =B33 -> 129.64904 | C43: Low EV/Revenue and low EV/EBITDA case
A44: Base Case | B44: =D35 -> 156.03353 | C44: Selected median / median blended case
A45: Upside | B45: =F37 -> 182.41802 | C45: High EV/Revenue and high EV/EBITDA case
A47: The two-way table varies both selected median multiples around the base case. The base-case blended value is linked directly to the PTA Valuation tab; downside and upside are analytical scenarios, not forecasts or company guidance.

Sheet Football Field
A1: FOOTBALL FIELD — IMPLIED SHARE PRICE RANGES
A2: 25th percentile to 75th percentile valuation ranges | $ per share
A4: VALUATION RANGE DATA
A5: Method | B5: Low (25th) | C5: Median | D5: High (75th) | E5: Range Width
A6: EV / Revenue | B6: ='PTA Valuation'!I17 -> 102.72662 | C6: ='PTA Valuation'!I18 -> 135.90802 | D6: ='PTA Valuation'!I19 -> 148.64043 | E6: =D6-B6 -> 45.913808
A7: EV / Adjusted EBITDA | B7: ='PTA Valuation'!I25 -> 155.72947 | C7: ='PTA Valuation'!I26 -> 176.15905 | D7: ='PTA Valuation'!I27 -> 206.25251 | E7: =D7-B7 -> 50.523037
A10: REFERENCE PRICES
A11: Reference | B11: Price | C11: Interpretation
A12: Unaffected Share Price | B12: ='PTA Valuation'!B10 -> 171.65 | C12: 28-Jul-2025 close
A13: Baker Hughes Offer Price | B13: ='PTA Valuation'!B11 -> 210 | C13: Cash offer
A14: Selected PTA Base Case | B14: ='PTA Valuation'!B40 -> 156.03353 | C14: Blended median
A18: The 25th–75th percentile ranges reduce reliance on extremes. Emerson / National Instruments' 30.6x standardized-EBITDA observation is retained in the raw set but does not set the displayed range.
A19: The disclosed ~9.0x forward, synergy-adjusted Baker Hughes / Chart multiple is intentionally excluded from the historical PTA; see Transaction Overview and Dashboard.
A22: REFERENCE PRICE COMPARISON
A23: Reference | B23: Price / Share
A24: Unaffected Share Price | B24: ='PTA Valuation'!B10 -> 171.65
A25: Blended PTA Valuation | B25: ='PTA Valuation'!B40 -> 156.03353
A26: Baker Hughes Offer Price | B26: ='PTA Valuation'!B11 -> 210

Sheet Transaction Screening
A1: TRANSACTION SCREENING — COMPARABILITY ASSESSMENT
A2: Comparability criteria scored 1 (low) to 5 (high) | Supports qualitative assessment; data completeness determines statistical inclusion.
A4: SCREENING CRITERIA
A5: Criterion | B5: Weight | C5: Description
A6: Industry Similarity | B6: 1 | C6: Overlap with flow control, compression and industrial process technology end markets
A7: Business Model | B7: 1 | C7: Mix of equipment sales vs. recurring aftermarket / service revenue
A8: Size | B8: 1 | C8: Enterprise value scale relative to the focal transaction
A9: Strategic Rationale | B9: 1 | C9: Similarity of stated acquisition rationale (portfolio, end-market, aftermarket expansion)
A10: Recency | B10: 1 | C10: Proximity of announcement date to the focal transaction
A11: Data Availability | B11: 1 | C11: Reliability and completeness of disclosed EV, revenue, EBITDA and pricing data
A13: SCREENING SCORES — CORE PRECEDENT SET
A14: Transaction | B14: Industry Similarity | C14: Business Model | D14: Size | E14: Strategic Rationale | F14: Recency | G14: Data Availability | H14: Total / 30 | I14: Overall Comparability (%)
A15: ='Precedent Transactions'!B6&" / "&'Precedent Transactions'!C6 -> Flowserve / Velan | B15: ='Precedent Transactions'!B24 -> 5 | C15: ='Precedent Transactions'!C24 -> 5 | D15: ='Precedent Transactions'!D24 -> 2 | E15: ='Precedent Transactions'!E24 -> 5 | F15: ='Precedent Transactions'!F24 -> 5 | G15: ='Precedent Transactions'!G24 -> 5 | H15: =SUM(B15:G15) -> 27 | I15: =H15/30 -> 0.9
A16: ='Precedent Transactions'!B7&" / "&'Precedent Transactions'!C7 -> SLB / ChampionX | B16: ='Precedent Transactions'!B25 -> 4 | C16: ='Precedent Transactions'!C25 -> 4 | D16: ='Precedent Transactions'!D25 -> 5 | E16: ='Precedent Transactions'!E25 -> 5 | F16: ='Precedent Transactions'!F25 -> 5 | G16: ='Precedent Transactions'!G25 -> 5 | H16: =SUM(B16:G16) -> 28 | I16: =H16/30 -> 0.93333333
A17: ='Precedent Transactions'!B8&" / "&'Precedent Transactions'!C8 -> Emerson / National Instruments | B17: ='Precedent Transactions'!B26 -> 4 | C17: ='Precedent Transactions'!C26 -> 4 | D17: ='Precedent Transactions'!D26 -> 5 | E17: ='Precedent Transactions'!E26 -> 4 | F17: ='Precedent Transactions'!F26 -> 5 | G17: ='Precedent Transactions'!G26 -> 5 | H17: =SUM(B17:G17) -> 27 | I17: =H17/30 -> 0.9
A18: ='Precedent Transactions'!B9&" / "&'Precedent Transactions'!C9 -> Regal Rexnord / Altra Industrial Motion | B18: ='Precedent Transactions'!B27 -> 4 | C18: ='Precedent Transactions'!C27 -> 5 | D18: ='Precedent Transactions'!D27 -> 4 | E18: ='Precedent Transactions'!E27 -> 5 | F18: ='Precedent Transactions'!F27 -> 5 | G18: ='Precedent Transactions'!G27 -> 5 | H18: =SUM(B18:G18) -> 28 | I18: =H18/30 -> 0.93333333
A19: ='Precedent Transactions'!B10&" / "&'Precedent Transactions'!C10 -> Chart Industries / Howden | B19: ='Precedent Transactions'!B28 -> 5 | C19: ='Precedent Transactions'!C28 -> 5 | D19: ='Precedent Transactions'!D28 -> 4 | E19: ='Precedent Transactions'!E28 -> 5 | F19: ='Precedent Transactions'!F28 -> 5 | G19: ='Precedent Transactions'!G28 -> 5 | H19: =SUM(B19:G19) -> 29 | I19: =H19/30 -> 0.96666667
A20: ='Precedent Transactions'!B11&" / "&'Precedent Transactions'!C11 -> Siemens / Dresser-Rand | B20: ='Precedent Transactions'!B29 -> 5 | C20: ='Precedent Transactions'!C29 -> 5 | D20: ='Precedent Transactions'!D29 -> 5 | E20: ='Precedent Transactions'!E29 -> 5 | F20: ='Precedent Transactions'!F29 -> 2 | G20: ='Precedent Transactions'!G29 -> 5 | H20: =SUM(B20:G20) -> 27 | I20: =H20/30 -> 0.9
A21: ='Precedent Transactions'!B12&" / "&'Precedent Transactions'!C12 -> KKR / Gardner Denver | B21: ='Precedent Transactions'!B30 -> 4 | C21: ='Precedent Transactions'!C30 -> 5 | D21: ='Precedent Transactions'!D30 -> 4 | E21: ='Precedent Transactions'!E30 -> 4 | F21: ='Precedent Transactions'!F30 -> 1 | G21: ='Precedent Transactions'!G30 -> 5 | H21: =SUM(B21:G21) -> 23 | I21: =H21/30 -> 0.76666667
A22: ='Precedent Transactions'!B13&" / "&'Precedent Transactions'!C13 -> Caterpillar / Bucyrus | B22: ='Precedent Transactions'!B31 -> 4 | C22: ='Precedent Transactions'!C31 -> 4 | D22: ='Precedent Transactions'!D31 -> 5 | E22: ='Precedent Transactions'!E31 -> 5 | F22: ='Precedent Transactions'!F31 -> 1 | G22: ='Precedent Transactions'!G31 -> 5 | H22: =SUM(B22:G22) -> 24 | I22: =H22/30 -> 0.8
A24: SCREENING OUTCOME AND STATISTICAL INCLUSION
A25: Transaction | B25: Total Score / 30 | C25: Statistical Inclusion | D25: Comparability (%)
A26: =A15 -> Flowserve / Velan | B26: =H15 -> 27 | C26: ='Precedent Transactions'!U6 -> Core — both | D26: =I15 -> 0.9
A27: =A16 -> SLB / ChampionX | B27: =H16 -> 28 | C27: ='Precedent Transactions'!U7 -> Core — both | D27: =I16 -> 0.93333333
A28: =A17 -> Emerson / National Instruments | B28: =H17 -> 27 | C28: ='Precedent Transactions'!U8 -> Core — both | D28: =I17 -> 0.9
A29: =A18 -> Regal Rexnord / Altra Industrial Motion | B29: =H18 -> 28 | C29: ='Precedent Transactions'!U9 -> Core — both | D29: =I18 -> 0.93333333
A30: =A19 -> Chart Industries / Howden | B30: =H19 -> 29 | C30: ='Precedent Transactions'!U10 -> Core — both | D30: =I19 -> 0.96666667
A31: =A20 -> Siemens / Dresser-Rand | B31: =H20 -> 27 | C31: ='Precedent Transactions'!U11 -> Core — both | D31: =I20 -> 0.9
A32: =A21 -> KKR / Gardner Denver | B32: =H21 -> 23 | C32: ='Precedent Transactions'!U12 -> Core — both | D32: =I21 -> 0.76666667
A33: =A22 -> Caterpillar / Bucyrus | B33: =H22 -> 24 | C33: ='Precedent Transactions'!U13 -> Core — both | D33: =I22 -> 0.8
A35: SUPPLEMENTAL / EXCLUDED REFERENCE TRANSACTIONS
A36: Transaction | B36: Reason for Exclusion from Core Statistics
A37: ='Precedent Transactions'!B18&" / "&'Precedent Transactions'!C18 -> Honeywell / Sundyne | B37: ='Precedent Transactions'!U18 -> Supplemental — EV/EBITDA only; revenue not disclosed
A38: ='Precedent Transactions'!B19&" / "&'Precedent Transactions'!C19 -> GE / Lufkin Industries | B38: ='Precedent Transactions'!U19 -> Supplemental — forward / mismatched period
A40: Comparability scores are an analyst assessment of business similarity, strategic fit, transaction size, recency and data quality. All eight verified core transactions remain in the core statistical set regardless of score; supplemental transactions are excluded only for missing or mismatched required data.

Sheet Sources & Checks
A1: SOURCE REGISTER AND DATA QUALITY CHECKS
A2: Primary company and SEC materials prioritized | URLs recorded for every major input
